<?xml version="1.0" ?>
<sdf version="1.10">
    <model name="firebird_vi">

        <link name="base_link">
            <pose> 0.0 0.0 0.016 0 0 0 </pose>
            <visual name='visual'>
                <geometry>
                    <mesh>
                        <uri>package://robot_description/meshes/firebird_vi.obj</uri>
                    </mesh>
                </geometry>
            </visual>
            <collision name="collision">
            <pose> 0 0 0.1 0 0 0</pose>
                <geometry>
                    <cylinder>
                        <radius> 0.125 </radius>
                        <length> 0.20 </length>
                    </cylinder>
                </geometry>
            </collision>
            <inertial>
                <pose> 0 0 0.046498 0 0 0 </pose>
                <mass>10</mass> 
                <inertia>
                    <ixx>1.765E-02</ixx>
                    <ixy>-2.217E-17</ixy>
                    <ixz>-2.225197E-06</ixz>
                    <iyy>1.663E-02</iyy>
                    <iyz>2.217E-17</iyz>
                    <izz>1.932E-02</izz>
                </inertia>
            </inertial>
        </link>

        <link name="front_right_wheel">
            <pose> 0.0835 -0.37975 0.03 0 0 0 </pose>
            <visual name='visual'>
                <geometry>
                    <mesh>
                        <uri>package://robot_description/meshes/firebird_wheel.obj</uri>
                    </mesh>
                </geometry>
            </visual>
            <collision name="collision">
            <pose> 0 0.255875 0 1.57 0 0</pose>
                <geometry>
                    <cylinder>
                        <radius> 0.04 </radius>
                        <length> 0.02 </length>
                    </cylinder>
                </geometry>
                <surface>
                    <friction>
                        <ode>
                            <mu>1</mu>
                            <mu2>1</mu2>
                            <slip1>0.035</slip1>
                            <slip2>0</slip2>
                            <fdir1>0 0 1</fdir1>
                        </ode>
                    </friction>
                </surface>
            </collision>
            <inertial>
                <pose> 0 0.256506 0 0 0 0 </pose>
                <mass>0.1</mass>
                    <inertia>
                    <ixx>0.000043333</ixx>
                    <ixy>0</ixy>
                    <ixz>0</ixz>
                    <iyy>0.00008</iyy>
                    <iyz>0</iyz>
                    <izz>0.000043333</izz>
                </inertia> 
            </inertial>
        </link>

        <link name="front_left_wheel">
            <pose> 0.0835 -0.13325 0.03 0 0 0</pose>
            <visual name='visual'>
                <geometry>
                    <mesh>
                        <uri>package://robot_description/meshes/firebird_wheel.obj</uri>
                    </mesh>
                </geometry>
            </visual>
            <collision name="collision">
            <pose> 0 0.255875 0 1.57 0 0</pose>
                <geometry>
                    <cylinder>
                        <radius> 0.04 </radius>
                        <length> 0.02 </length>
                    </cylinder>
                </geometry>
                <surface>
                    <friction>
                    <ode>
                        <mu>1</mu>
                        <mu2>1</mu2>
                        <slip1>0.035</slip1>
                        <slip2>0</slip2>
                        <fdir1>0 0 1</fdir1>
                    </ode>
                    <bullet>
                        <friction>1</friction>
                        <friction2>1</friction2>
                        <rolling_friction>0.1</rolling_friction>
                        <spinning_friction>0.1</spinning_friction>
                    </bullet>
                    </friction>
                </surface>
            </collision>
            <inertial>
                <pose> 0 0.256506 0 0 0 0 </pose>
                <mass>0.1</mass>
                    <inertia>
                    <ixx>0.000043333</ixx>
                    <ixy>0</ixy>
                    <ixz>0</ixz>
                    <iyy>0.00008</iyy>
                    <iyz>0</iyz>
                    <izz>0.000043333</izz>
                </inertia> 
            </inertial>
        </link>

        <link name="rear_right_wheel">
            <pose>-0.0835 -0.37975 0.03 0 0 0</pose>
            <visual name='visual'>
                <geometry>
                    <mesh>
                        <uri>package://robot_description/meshes/firebird_wheel.obj</uri>
                    </mesh>
                </geometry>
            </visual>
            <collision name="collision">
            <pose> 0 0.255875 0 1.57 0 0</pose>
                <geometry>
                    <cylinder>
                        <radius> 0.04 </radius>
                        <length> 0.02 </length>
                    </cylinder>
                </geometry>
                <surface>
                    <friction>
                    <ode>
                        <mu>1</mu>
                        <mu2>1</mu2>
                        <slip1>0.035</slip1>
                        <slip2>0</slip2>
                        <fdir1>0 0 1</fdir1>
                    </ode>
                    <bullet>
                        <friction>1</friction>
                        <friction2>1</friction2>
                        <rolling_friction>0.1</rolling_friction>
                        <spinning_friction>0.1</spinning_friction>
                    </bullet>
                    </friction>
                </surface>
            </collision>
            <inertial>
                <pose> 0 0.256506 0 0 0 0 </pose>
                <mass>0.1</mass>
                    <inertia>
                    <ixx>0.000043333</ixx>
                    <ixy>0</ixy>
                    <ixz>0</ixz>
                    <iyy>0.00008</iyy>
                    <iyz>0</iyz>
                    <izz>0.000043333</izz>
                </inertia> 
            </inertial>
        </link>

        <link name="rear_left_wheel">
            <pose>-0.0835 -0.13325 0.03 0 0 0</pose>
            <visual name='visual'>
                <geometry>
                    <mesh>
                        <uri>package://robot_description/meshes/firebird_wheel.obj</uri>
                    </mesh>
                </geometry>
            </visual>
            <collision name="collision">
            <pose> 0 0.255875 0 1.57 0 0</pose>
                <geometry>
                    <cylinder>
                        <radius> 0.04 </radius>
                        <length> 0.02 </length>
                    </cylinder>
                </geometry>
            </collision>
            <surface>
                    <friction>
                    <ode>
                        <mu>1</mu>
                        <mu2>1</mu2>
                        <slip1>0.035</slip1>
                        <slip2>0</slip2>
                        <fdir1>0 0 1</fdir1>
                    </ode>
                    <bullet>
                        <friction>1</friction>
                        <friction2>1</friction2>
                        <rolling_friction>0.1</rolling_friction>
                        <spinning_friction>0.1</spinning_friction>
                    </bullet>
                    </friction>
                </surface>
            <inertial>
                <pose> 0 0.256506 0 0 0 0 </pose>
                <mass>0.1</mass>
                    <inertia>
                    <ixx>0.000043333</ixx>
                    <ixy>0</ixy>
                    <ixz>0</ixz>
                    <iyy>0.00008</iyy>
                    <iyz>0</iyz>
                    <izz>0.000043333</izz>
                </inertia> 
            </inertial>
        </link>

        <joint name='front_left' type='revolute'>
            <pose> 0 0.256506 0 0 0 0</pose>
            <parent>base_link</parent>
            <child>front_left_wheel</child>
            <axis>
                <xyz expressed_in='__model__'>0 1 0</xyz>
                <limit>
                    <lower>-1.79769e+308</lower>    <!--negative infinity-->
                    <upper>1.79769e+308</upper>     <!--positive infinity-->
                </limit>
            </axis>
        </joint>

        <joint name='front_right' type='revolute'>
            <pose> 0 0.256506 0 0 0 0</pose>
            <parent>base_link</parent>
            <child>front_right_wheel</child>
            <axis>
                <xyz expressed_in='__model__'>0 1 0</xyz>
                <limit>
                    <lower>-1.79769e+308</lower>    <!--negative infinity-->
                    <upper>1.79769e+308</upper>     <!--positive infinity-->
                </limit>
            </axis>
        </joint>

        <joint name='rear_left' type='revolute'>
            <pose> 0 0.256506 0 0 0 0</pose>
            <parent>base_link</parent>
            <child>rear_left_wheel</child>
            <axis>
                <xyz expressed_in='__model__'>0 1 0</xyz>
                <limit>
                    <lower>-1.79769e+308</lower>    <!--negative infinity-->
                    <upper>1.79769e+308</upper>     <!--positive infinity-->
                </limit>
            </axis>
        </joint>

        <joint name='rear_right' type='revolute'>
            <pose> 0 0.256506 0 0 0 0</pose>
            <parent>base_link</parent>
            <child>rear_right_wheel</child>
            <axis>
                <xyz expressed_in='__model__'>0 1 0</xyz>
                <limit>
                    <lower>-1.79769e+308</lower>    <!--negative infinity-->
                    <upper>1.79769e+308</upper>     <!--positive infinity-->
                </limit>
            </axis>
        </joint>

        <plugin filename="gz-sim-diff-drive-system" name="gz::sim::systems::DiffDrive">
            <left_joint>rear_left</left_joint>
            <left_joint>front_left</left_joint>
            <right_joint>rear_right</right_joint>
            <right_joint>front_right</right_joint>
            <wheel_separation>0.2465</wheel_separation>
            <wheel_radius>0.04</wheel_radius>
            <odom_publish_frequency>1</odom_publish_frequency>
            <max_linear_acceleration>1</max_linear_acceleration>
            <min_linear_acceleration>-1</min_linear_acceleration>
            <max_angular_acceleration>2</max_angular_acceleration>
            <min_angular_acceleration>-2</min_angular_acceleration>
            <max_linear_velocity>0.5</max_linear_velocity>
            <min_linear_velocity>-0.5</min_linear_velocity>
            <max_angular_velocity>1</max_angular_velocity>
            <min_angular_velocity>-1</min_angular_velocity>
            <topic>cmd_vel</topic>
        </plugin>

        <plugin
            filename="gz-sim-joint-state-publisher-system"
            name="gz::sim::systems::JointStatePublisher">
        </plugin>

        <plugin
            filename="gz-sim-pose-publisher-system"
            name="gz::sim::systems::PosePublisher">
            <publish_link_pose>true</publish_link_pose>
            <use_pose_vector_msg>true</use_pose_vector_msg>
            <static_publisher>true</static_publisher>
            <static_update_frequency>1</static_update_frequency>
        </plugin>

        <plugin
            filename="gz-sim-odometry-publisher-system"
            name="gz::sim::systems::OdometryPublisher">
            <odom_frame>odom</odom_frame>
            <robot_base_frame>base_link</robot_base_frame>
        </plugin>

    </model>
</sdf>