<?xml version="1.0"?>
<robot name="4w_diff_drive">
    <link name="base_link">    
        <visual>
            <origin xyz="0.0 0.0 0.12" rpy="0.0 0.0 0.0"/>
            <geometry>
                <box size="0.3 0.2 0.15"/>
            </geometry>
        </visual>
    </link>
    <link name="front_left_wheel">
        <visual>
            <origin xyz="0 0 0" rpy="1.57 0.0 0.0"/>
            <geometry>
                <cylinder radius="0.08" length="0.02"/>
            </geometry>
        </visual>        
    </link>
    <link name="front_right_wheel">
        <visual>
            <origin xyz="0 0 0" rpy="1.57 0.0 0.0"/>
            <geometry>
                <cylinder radius="0.08" length="0.02"/>
            </geometry>
        </visual>        
    </link>
    <link name="rear_left_wheel">
        <visual>
            <origin xyz="0 0 0" rpy="1.57 0.0 0.0"/>
            <geometry>
                <cylinder radius="0.08" length="0.02"/>
            </geometry>
        </visual>        
    </link>
    <link name="rear_right_wheel">
        <visual>
            <origin xyz="0 0 0" rpy="1.57 0.0 0.0"/>
            <geometry>
                <cylinder radius="0.08" length="0.02"/>
            </geometry>
        </visual>        
    </link>

    <joint name="front_left_wheel_link" type="continuous">
        <parent link="base_link"/>
        <child link="front_left_wheel"/>
        <axis xyz="0 1 0"/>
        <origin xyz="0.15 0.11 0.04" rpy="0 0 0"/>
    </joint>

    <joint name="front_right_wheel_link" type="continuous">
        <parent link="base_link"/>
        <child link="front_right_wheel"/>
        <axis xyz="0 1 0"/>
        <origin xyz="0.15 -0.11 0.04" rpy="0 0 0"/>
    </joint>

    <joint name="rear_left_wheel_link" type="continuous">
        <parent link="base_link"/>
        <child link="rear_left_wheel"/>
        <axis xyz="0 1 0"/>
        <origin xyz="-0.15 0.11 0.04" rpy="0 0 0"/>
    </joint>

    <joint name="rear_right_wheel_link" type="continuous">
        <parent link="base_link"/>
        <child link="rear_right_wheel"/>
        <axis xyz="0 1 0"/>
        <origin xyz="-0.15 -0.11 0.04" rpy="0 0 0"/>
    </joint>
    
</robot>