<robot name="firebird_vi">

    <material name="grey">
        <color rgba='0.66274509803 0.66274509803 0.66274509803 1' />
    </material>

    <material name="red">
        <color rgba='1 0 0 1' />
    </material>

    <link name="base_link">
    <origin xyz="0.0 0.0 0.016" rpy="0.0 0.0 0.0"/>
         <visual>
            <geometry>
                <mesh filename="package://robot_description/meshes/firebird_vi.obj"/>
            </geometry>
            <material name='red'/>
        </visual>
        <collision>
            <geometry>
                <cylinder radius="0.1250" length="0.2"/>
            </geometry>
        </collision>
        <inertial>
            <mass value="2"/>
            <inertia ixx="1" ixy="0.0" ixz="0.0" iyy="1" iyz="0.0" izz="1"/>
        </inertial>
    </link>

    <link name="front_right_wheel">
        <visual>
            <origin xyz="0.0835 -0.37975 0.03" rpy="0.0 0.0 0.0"/>
            <geometry>
                <mesh filename="package://robot_description/meshes/firebird_wheel.obj"/>
            </geometry>
            <material name="grey"/>
        </visual>
        <inertial>
            <mass value="0.1"/>
            <inertia ixx="1" ixy="0.0" ixz="0.0" iyy="1" iyz="0.0" izz="1"/>
        </inertial>
    </link>

    <link name="front_left_wheel">
        <visual>
            <origin xyz="0.0835 -0.13325 0.03" rpy="0.0 0.0 0.0"/>
            <geometry>
                <mesh filename="package://robot_description/meshes/firebird_wheel.obj"/>
            </geometry>
            <material name="grey"/>
        </visual>
        <inertial>
            <mass value="0.1"/>
            <inertia ixx="1" ixy="0.0" ixz="0.0" iyy="1" iyz="0.0" izz="1"/>
        </inertial>
    </link>

    <link name="back_right_wheel">
        <visual>
            <origin xyz="-0.0835 -0.37975 0.03" rpy="0.0 0.0 0.0"/>
            <geometry>
                <mesh filename="package://robot_description/meshes/firebird_wheel.obj"/>
            </geometry>
            <material name="grey"/>
        </visual>
        <inertial>
            <mass value="0.1"/>
            <inertia ixx="1" ixy="0.0" ixz="0.0" iyy="1" iyz="0.0" izz="1"/>
        </inertial>
    </link>

    <link name="back_left_wheel">
        <visual>
        <origin xyz="0.0835 -0.13325 0.03" rpy="0.0 0.0 0.0"/>
            <geometry>
                <mesh filename="package://robot_description/meshes/firebird_wheel.obj"/>
            </geometry>
            <material name="grey"/>
        </visual>
        <inertial>
            <mass value="0.1"/>
            <inertia ixx="1" ixy="0.0" ixz="0.0" iyy="1" iyz="0.0" izz="1"/>
        </inertial>
    </link>

    <joint name="front_right_wheel_base_link" type="continuous">
        <parent link="base_link"/>
        <child link="front_right_wheel"/>
        <axis xyz="0.0 1.0 0.0"/>
    </joint>

    <joint name="front_left_wheel_base_link" type="continuous">
        <parent link="base_link"/>
        <child link="front_left_wheel"/>
        <axis xyz="0.0 1.0 0.0"/>
    </joint>

    <joint name="back_right_wheel_base_link" type="continuous">
        <parent link="base_link"/>
        <child link="back_right_wheel"/>
        <axis xyz="0.0 1.0 0.0"/>
    </joint>

    <joint name="back_left_wheel_base_link" type="continuous">
        <parent link="base_link"/>
        <child link="back_left_wheel"/>
        <axis xyz="0.0 1.0 0.0"/>
    </joint>

</robot>